Workbook

Sheet Dashboard
A1: 🏆 Rahul — Warrior Physique Tracker
A2: 16-Week V-Taper + Combat Program | Start Date: Fill in | Target: 68–70 kg @ 13–15% BF
A5: Current Weight (kg) | C5: Body Fat % | E5: Lean Mass (kg) | G5: Fat Mass (kg) | I5: Visceral Fat | K5: Waist (cm)
A6: {=IF(COUNTA('Body Measurements'!B:B)>1,INDEX('Body Measurements'!B:B,COUNTA('Body Measurements'!B:B)),"—")} -> 0 | C6: {=IF(COUNTA('Body Measurements'!D:D)>1,INDEX('Body Measurements'!D:D,COUNTA('Body Measurements'!D:D)),"—")} -> 0 | E6: {=IF(COUNTA('Body Measurements'!F:F)>1,INDEX('Body Measurements'!F:F,COUNTA('Body Measurements'!F:F)),"—")} -> 0 | G6: {=IF(COUNTA('Body Measurements'!E:E)>1,INDEX('Body Measurements'!E:E,COUNTA('Body Measurements'!E:E)),"—")} -> 0 | I6: {=IF(COUNTA('Body Measurements'!G:G)>1,INDEX('Body Measurements'!G:G,COUNTA('Body Measurements'!G:G)),"—")} -> 0 | K6: {=IF(COUNTA('Body Measurements'!J:J)>1,INDEX('Body Measurements'!J:J,COUNTA('Body Measurements'!J:J)),"—")} -> 0
A9: STARTING STATS (Week 0 Baseline)
A10: Weight | C10: Height | E10: Age | G10: BMI | I10: Body Fat | K10: Lean Mass
A11: 77.8 kg | C11: 178 cm | E11: 35 yrs | G11: 24.6 | I11: 23.7% | K11: 59.4 kg
A12: Fat Mass | C12: Muscle Mass | E12: Visceral Fat | G12: BMR | I12: Waist | K12: Chest
A13: 18.4 kg | C13: 55.6 kg | E13: 8.8 | G13: ~1780 kcal | I13: 92.5 cm | K13: 101 cm
A15: TARGET GOALS
A16: Target Weight | C16: Target BF% | E16: Target Waist | G16: Target Shoulders | I16: Visceral Fat Target | K16: Program Duration
A17: 68–72 kg | C17: 13–15% | E17: 80–82 cm | G17: 116+ cm | I17: < 5.0 | K17: 16 weeks
A20: PHASE GUIDE
A21: Phase 1 | C21: Weeks 1–4 | E21: Foundation + Fat Attack | I21: 1900 kcal · 175g protein · Learn all movements
A22: Phase 2 | C22: Weeks 5–8 | E22: Hypertrophy + Combat Skill | I22: 1800 kcal · 180g protein · Supersets + bag combos
A23: Phase 3 | C23: Weeks 9–12 | E23: Strength + Power | I23: 1750 kcal · 185g protein · Explosive kicks + drops
A24: Phase 4 | C24: Weeks 13–16 | E24: Warrior Peak | I24: 1850 kcal · 180g protein · Max intensity + maintenance
A26: HOW TO USE THIS WORKBOOK
A27: 1. Body Measurements → Fill in every SUNDAY morning, fasted, same time each week
A28: 2. Nutrition Log → Fill in DAILY before bed. Be honest — this is your most important data.
A29: 3. Workout Log sheets (Push/Pull/Legs/Combat) → Fill in during or immediately after each session
A30: 4. Dashboard → Auto-updates from other sheets. Review weekly with your trainer (Claude)
A31: 5. Share this file link with me anytime and I will analyze your progress and adjust the program

Sheet Body Measurements
A1: 📏 Body Measurements — Weekly Tracker
A2: Weigh yourself SUNDAY morning, fasted, before eating. Same time every week.
A5: Week # | B5: Date | C5: Weight (kg) | D5: Body Fat (%) | E5: Fat Mass (kg) | F5: Lean Mass (kg) | G5: Visceral Fat | H5: Muscle Mass (kg) | I5: Subcutaneous Fat % | J5: Body Water (%) | K5: BMI | L5: Neck (cm) | M5: Shoulders (cm) | N5: Chest (cm) | O5: Waist (cm) | P5: Waist@Naval (cm) | Q5: Hips (cm) | R5: Thighs (cm) | S5: Bicep (cm) | T5: Forearm (cm) | U5: Calves (cm) | V5: Notes
A6: 0 (Baseline) | B6: Before start | C6: 77.8 | D6: 23.7 | E6: 18.4 | F6: 59.4 | G6: 8.8 | H6: 55.6 | I6: 15.9 | J6: 52.1 | K6: 24.6 | L6: 38 | M6: 112 | N6: 101 | O6: 96 | P6: 92 | Q6: 99.5 | R6: 61 | S6: 34 | T6: 26 | U6: 34.3 | V6: Starting baseline
A7: 1 | B7: 46118 | C7: 77.9 | L7: 38.5 | M7: 120 | N7: 99 | O7: 95 | P7: 92 | Q7: 101 | R7: 61 | S7: 36.5 | T7: 27.5 | U7: 35.5 | V7: Needs to start check workout
A8: 2
A9: 3
A10: 4
A11: 5
A12: 6
A13: 7
A14: 8
A15: 9
A16: 10
A17: 11
A18: 12
A19: 13
... A22: 16
A23: CHANGE vs BASELINE
C24: =IF(ISNUMBER(C22),C22-C6,"—") -> — | D24: =IF(ISNUMBER(D22),D22-D6,"—") -> — | E24: =IF(ISNUMBER(E22),E22-E6,"—") -> — | F24: =IF(ISNUMBER(F22),F22-F6,"—") -> — | G24: =IF(ISNUMBER(G22),G22-G6,"—") -> — | H24: =IF(ISNUMBER(H22),H22-H6,"—") -> — | I24: =IF(ISNUMBER(I22),I22-I6,"—") -> — | J24: =IF(ISNUMBER(J22),J22-J6,"—") -> — | ... U24: =IF(ISNUMBER(U22),U22-U6,"—") -> —

Sheet Exercise Plan
A1: 💪 Push Day — Session Log
A2: Fill in: Date · Week · Phase · then each exercise. Log every set as you do it.
A3: Date: | C3: Week #: | E3: Phase (1–4): | G3: Day (A or B): | H3: Monday | I3: Session #: | J3: 1 | K3: Duration (min): | M3: Energy 1–10: | O3: Notes:
A4: Push A - Chest, Shoulders, Triceps | B4: Notes / Cues | C4: Set 1 Weight (kg) | D4: Set 1 Reps | E4: Set 1 1RM | F4: Set 2 Weight (kg) | G4: Set 2 Reps | H4: Set 2 1RM | I4: Set 3 Weight (kg) | J4: Set 3 Reps | K4: Set 3 1RM | L4: Set 4 Weight (kg) | M4: Set 4 Reps | N4: Set 4 1RM | O4: Set 5 Weight (kg) | P4: Set 5 Reps | Q4: Set 5 1RM | R4: Best 1RM Today | S4: Default Sets | T4: Default Reps
A5: Arm circles + shoulder rolls | B5: 60 sec each direction | E5: =IF(AND(ISNUMBER(C5),ISNUMBER(D5)),ROUND(C5*(1+D5/30),1),"—") -> — | H5: =IF(AND(ISNUMBER(F5),ISNUMBER(G5)),ROUND(F5*(1+G5/30),1),"—") -> — | K5: =IF(AND(ISNUMBER(I5),ISNUMBER(J5)),ROUND(I5*(1+J5/30),1),"—") -> — | N5: =IF(AND(ISNUMBER(L5),ISNUMBER(M5)),ROUND(L5*(1+M5/30),1),"—") -> — | Q5: =IF(AND(ISNUMBER(O5),ISNUMBER(P5)),ROUND(O5*(1+P5/30),1),"—") -> — | R5: =IFERROR(MAX(IFERROR(VALUE(E5),0),IFERROR(VALUE(H5),0),IFERROR(VALUE(K5),0),IFERROR(VALUE(N5),0),IFERROR(VALUE(Q5),0)),"—") -> 0
A6: Band pull-apart | B6: 2x15 reps | E6: =IF(AND(ISNUMBER(C6),ISNUMBER(D6)),ROUND(C6*(1+D6/30),1),"—") -> — | H6: =IF(AND(ISNUMBER(F6),ISNUMBER(G6)),ROUND(F6*(1+G6/30),1),"—") -> — | K6: =IF(AND(ISNUMBER(I6),ISNUMBER(J6)),ROUND(I6*(1+J6/30),1),"—") -> — | N6: =IF(AND(ISNUMBER(L6),ISNUMBER(M6)),ROUND(L6*(1+M6/30),1),"—") -> — | Q6: =IF(AND(ISNUMBER(O6),ISNUMBER(P6)),ROUND(O6*(1+P6/30),1),"—") -> — | R6: =IFERROR(MAX(IFERROR(VALUE(E6),0),IFERROR(VALUE(H6),0),IFERROR(VALUE(K6),0),IFERROR(VALUE(N6),0),IFERROR(VALUE(Q6),0)),"—") -> 0
A7: Incline Push-ups | B7: slow 2x10 reps | E7: =IF(AND(ISNUMBER(C7),ISNUMBER(D7)),ROUND(C7*(1+D7/30),1),"—") -> — | H7: =IF(AND(ISNUMBER(F7),ISNUMBER(G7)),ROUND(F7*(1+G7/30),1),"—") -> — | K7: =IF(AND(ISNUMBER(I7),ISNUMBER(J7)),ROUND(I7*(1+J7/30),1),"—") -> — | N7: =IF(AND(ISNUMBER(L7),ISNUMBER(M7)),ROUND(L7*(1+M7/30),1),"—") -> — | Q7: =IF(AND(ISNUMBER(O7),ISNUMBER(P7)),ROUND(O7*(1+P7/30),1),"—") -> — | R7: =IFERROR(MAX(IFERROR(VALUE(E7),0),IFERROR(VALUE(H7),0),IFERROR(VALUE(K7),0),IFERROR(VALUE(N7),0),IFERROR(VALUE(Q7),0)),"—") -> 0
A8: Light Dumbell Lateral Raise | B8: 1x15 reps | C8: 2.5 | D8: 16 | E8: =IF(AND(ISNUMBER(C8),ISNUMBER(D8)),ROUND(C8*(1+D8/30),1),"—") -> 3.8 | H8: =IF(AND(ISNUMBER(F8),ISNUMBER(G8)),ROUND(F8*(1+G8/30),1),"—") -> — | K8: =IF(AND(ISNUMBER(I8),ISNUMBER(J8)),ROUND(I8*(1+J8/30),1),"—") -> — | N8: =IF(AND(ISNUMBER(L8),ISNUMBER(M8)),ROUND(L8*(1+M8/30),1),"—") -> — | Q8: =IF(AND(ISNUMBER(O8),ISNUMBER(P8)),ROUND(O8*(1+P8/30),1),"—") -> — | R8: =IFERROR(MAX(IFERROR(VALUE(E8),0),IFERROR(VALUE(H8),0),IFERROR(VALUE(K8),0),IFERROR(VALUE(N8),0),IFERROR(VALUE(Q8),0)),"—") -> 3.8
A9: Dumbbell flat bench press | B9: Bench. Full ROM, elbows 45°. Primary chest builder. | C9: 7.5 | D9: 15 | E9: =IF(AND(ISNUMBER(C9),ISNUMBER(D9)),ROUND(C9*(1+D9/30),1),"—") -> 11.3 | F9: 7.5 | G9: 16 | H9: =IF(AND(ISNUMBER(F9),ISNUMBER(G9)),ROUND(F9*(1+G9/30),1),"—") -> 11.5 | I9: 7.5 | J9: 20 | K9: =IF(AND(ISNUMBER(I9),ISNUMBER(J9)),ROUND(I9*(1+J9/30),1),"—") -> 12.5 | N9: =IF(AND(ISNUMBER(L9),ISNUMBER(M9)),ROUND(L9*(1+M9/30),1),"—") -> — | Q9: =IF(AND(ISNUMBER(O9),ISNUMBER(P9)),ROUND(O9*(1+P9/30),1),"—") -> — | R9: =IFERROR(MAX(IFERROR(VALUE(E9),0),IFERROR(VALUE(H9),0),IFERROR(VALUE(K9),0),IFERROR(VALUE(N9),0),IFERROR(VALUE(Q9),0)),"—") -> 12.5 | S9: 3 | T9: 12–15
A10: Dumbbell incline press | B10: 45° bench angle. Hits upper chest for V-taper. | C10: 7.5 | D10: 20 | E10: =IF(AND(ISNUMBER(C10),ISNUMBER(D10)),ROUND(C10*(1+D10/30),1),"—") -> 12.5 | F10: 7.5 | G10: 20 | H10: =IF(AND(ISNUMBER(F10),ISNUMBER(G10)),ROUND(F10*(1+G10/30),1),"—") -> 12.5 | I10: 7.5 | J10: 15 | K10: =IF(AND(ISNUMBER(I10),ISNUMBER(J10)),ROUND(I10*(1+J10/30),1),"—") -> 11.3 | N10: =IF(AND(ISNUMBER(L10),ISNUMBER(M10)),ROUND(L10*(1+M10/30),1),"—") -> — | Q10: =IF(AND(ISNUMBER(O10),ISNUMBER(P10)),ROUND(O10*(1+P10/30),1),"—") -> — | R10: =IFERROR(MAX(IFERROR(VALUE(E10),0),IFERROR(VALUE(H10),0),IFERROR(VALUE(K10),0),IFERROR(VALUE(N10),0),IFERROR(VALUE(Q10),0)),"—") -> 12.5 | S10: 3 | T10: 15
A11: Dumbbell lateral raise | B11: Slow eccentric 3 sec. KEY for shoulder width. | C11: 5 | D11: 15 | E11: =IF(AND(ISNUMBER(C11),ISNUMBER(D11)),ROUND(C11*(1+D11/30),1),"—") -> 7.5 | F11: 7.5 | G11: 10 | H11: =IF(AND(ISNUMBER(F11),ISNUMBER(G11)),ROUND(F11*(1+G11/30),1),"—") -> 10 | I11: 7.5 | J11: 10 | K11: =IF(AND(ISNUMBER(I11),ISNUMBER(J11)),ROUND(I11*(1+J11/30),1),"—") -> 10 | N11: =IF(AND(ISNUMBER(L11),ISNUMBER(M11)),ROUND(L11*(1+M11/30),1),"—") -> — | Q11: =IF(AND(ISNUMBER(O11),ISNUMBER(P11)),ROUND(O11*(1+P11/30),1),"—") -> — | R11: =IFERROR(MAX(IFERROR(VALUE(E11),0),IFERROR(VALUE(H11),0),IFERROR(VALUE(K11),0),IFERROR(VALUE(N11),0),IFERROR(VALUE(Q11),0)),"—") -> 10 | S11: 3 | T11: 12–15
A12: Standing dumbbell OHP | B12: Core braced. Don't flare elbows excessively. | C12: 7.5 | D12: 10 | E12: =IF(AND(ISNUMBER(C12),ISNUMBER(D12)),ROUND(C12*(1+D12/30),1),"—") -> 10 | F12: 10 | G12: 10 | H12: =IF(AND(ISNUMBER(F12),ISNUMBER(G12)),ROUND(F12*(1+G12/30),1),"—") -> 13.3 | I12: 15 | J12: 7 | K12: =IF(AND(ISNUMBER(I12),ISNUMBER(J12)),ROUND(I12*(1+J12/30),1),"—") -> 18.5 | N12: =IF(AND(ISNUMBER(L12),ISNUMBER(M12)),ROUND(L12*(1+M12/30),1),"—") -> — | Q12: =IF(AND(ISNUMBER(O12),ISNUMBER(P12)),ROUND(O12*(1+P12/30),1),"—") -> — | R12: =IFERROR(MAX(IFERROR(VALUE(E12),0),IFERROR(VALUE(H12),0),IFERROR(VALUE(K12),0),IFERROR(VALUE(N12),0),IFERROR(VALUE(Q12),0)),"—") -> 18.5 | S12: 3 | T12: 12–15
A13: Cable/Band Chest Fly | B13: Deep stretch. Peak chest contraction. | C13: 15 | D13: 10 | E13: =IF(AND(ISNUMBER(C13),ISNUMBER(D13)),ROUND(C13*(1+D13/30),1),"—") -> 20 | F13: 15 | G13: 13 | H13: =IF(AND(ISNUMBER(F13),ISNUMBER(G13)),ROUND(F13*(1+G13/30),1),"—") -> 21.5 | I13: 15 | J13: 17 | K13: =IF(AND(ISNUMBER(I13),ISNUMBER(J13)),ROUND(I13*(1+J13/30),1),"—") -> 23.5 | N13: =IF(AND(ISNUMBER(L13),ISNUMBER(M13)),ROUND(L13*(1+M13/30),1),"—") -> — | Q13: =IF(AND(ISNUMBER(O13),ISNUMBER(P13)),ROUND(O13*(1+P13/30),1),"—") -> — | R13: =IFERROR(MAX(IFERROR(VALUE(E13),0),IFERROR(VALUE(H13),0),IFERROR(VALUE(K13),0),IFERROR(VALUE(N13),0),IFERROR(VALUE(Q13),0)),"—") -> 23.5 | S13: 3 | T13: 15
A14: Tricep Cable/Band Pushdown | B14: Elbows fixed. Full extension. Triceps = 2/3 of arm. | C14: 15 | D14: 12 | E14: =IF(AND(ISNUMBER(C14),ISNUMBER(D14)),ROUND(C14*(1+D14/30),1),"—") -> 21 | F14: 15 | G14: 9 | H14: =IF(AND(ISNUMBER(F14),ISNUMBER(G14)),ROUND(F14*(1+G14/30),1),"—") -> 19.5 | I14: 15 | J14: 6 | K14: =IF(AND(ISNUMBER(I14),ISNUMBER(J14)),ROUND(I14*(1+J14/30),1),"—") -> 18 | N14: =IF(AND(ISNUMBER(L14),ISNUMBER(M14)),ROUND(L14*(1+M14/30),1),"—") -> — | Q14: =IF(AND(ISNUMBER(O14),ISNUMBER(P14)),ROUND(O14*(1+P14/30),1),"—") -> — | R14: =IFERROR(MAX(IFERROR(VALUE(E14),0),IFERROR(VALUE(H14),0),IFERROR(VALUE(K14),0),IFERROR(VALUE(N14),0),IFERROR(VALUE(Q14),0)),"—") -> 21 | S14: 3 | T14: 15
A15: Overhead DB Tricep Extension | B15: Long head stretch. Arms bigger from behind. | C15: 7.5 | D15: 14 | E15: =IF(AND(ISNUMBER(C15),ISNUMBER(D15)),ROUND(C15*(1+D15/30),1),"—") -> 11 | F15: 7.5 | G15: 11 | H15: =IF(AND(ISNUMBER(F15),ISNUMBER(G15)),ROUND(F15*(1+G15/30),1),"—") -> 10.3 | I15: 7.5 | J15: 11 | K15: =IF(AND(ISNUMBER(I15),ISNUMBER(J15)),ROUND(I15*(1+J15/30),1),"—") -> 10.3 | N15: =IF(AND(ISNUMBER(L15),ISNUMBER(M15)),ROUND(L15*(1+M15/30),1),"—") -> — | Q15: =IF(AND(ISNUMBER(O15),ISNUMBER(P15)),ROUND(O15*(1+P15/30),1),"—") -> — | R15: =IFERROR(MAX(IFERROR(VALUE(E15),0),IFERROR(VALUE(H15),0),IFERROR(VALUE(K15),0),IFERROR(VALUE(N15),0),IFERROR(VALUE(Q15),0)),"—") -> 11 | S15: 2 | T15: 15
A16: BAG: Straight Punch Rounds | B16: 3×1 min. Hands up. Exhale each punch. | E16: =IF(AND(ISNUMBER(C16),ISNUMBER(D16)),ROUND(C16*(1+D16/30),1),"—") -> — | H16: =IF(AND(ISNUMBER(F16),ISNUMBER(G16)),ROUND(F16*(1+G16/30),1),"—") -> — | K16: =IF(AND(ISNUMBER(I16),ISNUMBER(J16)),ROUND(I16*(1+J16/30),1),"—") -> — | N16: =IF(AND(ISNUMBER(L16),ISNUMBER(M16)),ROUND(L16*(1+M16/30),1),"—") -> — | Q16: =IF(AND(ISNUMBER(O16),ISNUMBER(P16)),ROUND(O16*(1+P16/30),1),"—") -> — | R16: =IFERROR(MAX(IFERROR(VALUE(E16),0),IFERROR(VALUE(H16),0),IFERROR(VALUE(K16),0),IFERROR(VALUE(N16),0),IFERROR(VALUE(Q16),0)),"—") -> 0
A17: Door-frame chest stretch | E17: =IF(AND(ISNUMBER(C17),ISNUMBER(D17)),ROUND(C17*(1+D17/30),1),"—") -> — | H17: =IF(AND(ISNUMBER(F17),ISNUMBER(G17)),ROUND(F17*(1+G17/30),1),"—") -> — | K17: =IF(AND(ISNUMBER(I17),ISNUMBER(J17)),ROUND(I17*(1+J17/30),1),"—") -> — | N17: =IF(AND(ISNUMBER(L17),ISNUMBER(M17)),ROUND(L17*(1+M17/30),1),"—") -> — | Q17: =IF(AND(ISNUMBER(O17),ISNUMBER(P17)),ROUND(O17*(1+P17/30),1),"—") -> — | R17: =IFERROR(MAX(IFERROR(VALUE(E17),0),IFERROR(VALUE(H17),0),IFERROR(VALUE(K17),0),IFERROR(VALUE(N17),0),IFERROR(VALUE(Q17),0)),"—") -> 0
A18: Across-body shoulder stretch | E18: =IF(AND(ISNUMBER(C18),ISNUMBER(D18)),ROUND(C18*(1+D18/30),1),"—") -> — | H18: =IF(AND(ISNUMBER(F18),ISNUMBER(G18)),ROUND(F18*(1+G18/30),1),"—") -> — | K18: =IF(AND(ISNUMBER(I18),ISNUMBER(J18)),ROUND(I18*(1+J18/30),1),"—") -> — | N18: =IF(AND(ISNUMBER(L18),ISNUMBER(M18)),ROUND(L18*(1+M18/30),1),"—") -> — | Q18: =IF(AND(ISNUMBER(O18),ISNUMBER(P18)),ROUND(O18*(1+P18/30),1),"—") -> — | R18: =IFERROR(MAX(IFERROR(VALUE(E18),0),IFERROR(VALUE(H18),0),IFERROR(VALUE(K18),0),IFERROR(VALUE(N18),0),IFERROR(VALUE(Q18),0)),"—") -> 0
A19: Tricep Overhead Stretch | E19: =IF(AND(ISNUMBER(C19),ISNUMBER(D19)),ROUND(C19*(1+D19/30),1),"—") -> — | H19: =IF(AND(ISNUMBER(F19),ISNUMBER(G19)),ROUND(F19*(1+G19/30),1),"—") -> — | K19: =IF(AND(ISNUMBER(I19),ISNUMBER(J19)),ROUND(I19*(1+J19/30),1),"—") -> — | N19: =IF(AND(ISNUMBER(L19),ISNUMBER(M19)),ROUND(L19*(1+M19/30),1),"—") -> — | Q19: =IF(AND(ISNUMBER(O19),ISNUMBER(P19)),ROUND(O19*(1+P19/30),1),"—") -> — | R19: =IFERROR(MAX(IFERROR(VALUE(E19),0),IFERROR(VALUE(H19),0),IFERROR(VALUE(K19),0),IFERROR(VALUE(N19),0),IFERROR(VALUE(Q19),0)),"—") -> 0
A20: Child's Pose | E20: =IF(AND(ISNUMBER(C20),ISNUMBER(D20)),ROUND(C20*(1+D20/30),1),"—") -> — | H20: =IF(AND(ISNUMBER(F20),ISNUMBER(G20)),ROUND(F20*(1+G20/30),1),"—") -> — | K20: =IF(AND(ISNUMBER(I20),ISNUMBER(J20)),ROUND(I20*(1+J20/30),1),"—") -> — | N20: =IF(AND(ISNUMBER(L20),ISNUMBER(M20)),ROUND(L20*(1+M20/30),1),"—") -> — | Q20: =IF(AND(ISNUMBER(O20),ISNUMBER(P20)),ROUND(O20*(1+P20/30),1),"—") -> — | R20: =IFERROR(MAX(IFERROR(VALUE(E20),0),IFERROR(VALUE(H20),0),IFERROR(VALUE(K20),0),IFERROR(VALUE(N20),0),IFERROR(VALUE(Q20),0)),"—") -> 0 | S20: 3 | T20: 1 min
A21: SESSION TOTAL SETS COMPLETED
A22: Progressive overload rule: If you complete ALL reps of ALL sets, INCREASE the weight by 1–2.5 kg next session.
A23: 💪 Pull Day — Session Log
A24: Fill in: Date · Week · Phase · then each exercise. Log every set as you do it.
A25: Date: | C25: Week #: | E25: Phase (1–4): | G25: Day (A or B): | H25: Tuesday | I25: Session #: | K25: Duration (min): | M25: Energy 1–10: | O25: Notes:
A26: Pull A | B26: Notes / Cues | C26: Set 1 Weight (kg) | D26: Set 1 Reps | E26: Set 1 1RM | F26: Set 2 Weight (kg) | G26: Set 2 Reps | H26: Set 2 1RM | I26: Set 3 Weight (kg) | J26: Set 3 Reps | K26: Set 3 1RM | L26: Set 4 Weight (kg) | M26: Set 4 Reps | N26: Set 4 1RM | O26: Set 5 Weight (kg) | P26: Set 5 Reps | Q26: Set 5 1RM | R26: Best 1RM Today | S26: Default Sets | T26: Default Reps
A27: Scapular wall slides | B27: back on wall and slide hands on wall 2x10 reps | E27: =IF(AND(ISNUMBER(C27),ISNUMBER(D27)),ROUND(C27*(1+D27/30),1),"—") -> — | H27: =IF(AND(ISNUMBER(F27),ISNUMBER(G27)),ROUND(F27*(1+G27/30),1),"—") -> — | K27: =IF(AND(ISNUMBER(I27),ISNUMBER(J27)),ROUND(I27*(1+J27/30),1),"—") -> — | N27: =IF(AND(ISNUMBER(L27),ISNUMBER(M27)),ROUND(L27*(1+M27/30),1),"—") -> — | Q27: =IF(AND(ISNUMBER(O27),ISNUMBER(P27)),ROUND(O27*(1+P27/30),1),"—") -> — | R27: =IFERROR(MAX(IFERROR(VALUE(E27),0),IFERROR(VALUE(H27),0),IFERROR(VALUE(K27),0),IFERROR(VALUE(N27),0),IFERROR(VALUE(Q27),0)),"—") -> 0
A28: Band face pull | B28: 2x15 reps | E28: =IF(AND(ISNUMBER(C28),ISNUMBER(D28)),ROUND(C28*(1+D28/30),1),"—") -> — | H28: =IF(AND(ISNUMBER(F28),ISNUMBER(G28)),ROUND(F28*(1+G28/30),1),"—") -> — | K28: =IF(AND(ISNUMBER(I28),ISNUMBER(J28)),ROUND(I28*(1+J28/30),1),"—") -> — | N28: =IF(AND(ISNUMBER(L28),ISNUMBER(M28)),ROUND(L28*(1+M28/30),1),"—") -> — | Q28: =IF(AND(ISNUMBER(O28),ISNUMBER(P28)),ROUND(O28*(1+P28/30),1),"—") -> — | R28: =IFERROR(MAX(IFERROR(VALUE(E28),0),IFERROR(VALUE(H28),0),IFERROR(VALUE(K28),0),IFERROR(VALUE(N28),0),IFERROR(VALUE(Q28),0)),"—") -> 0
A29: Dead hang on pull-up bar | B29: 2x20 sec | E29: =IF(AND(ISNUMBER(C29),ISNUMBER(D29)),ROUND(C29*(1+D29/30),1),"—") -> — | H29: =IF(AND(ISNUMBER(F29),ISNUMBER(G29)),ROUND(F29*(1+G29/30),1),"—") -> — | K29: =IF(AND(ISNUMBER(I29),ISNUMBER(J29)),ROUND(I29*(1+J29/30),1),"—") -> — | N29: =IF(AND(ISNUMBER(L29),ISNUMBER(M29)),ROUND(L29*(1+M29/30),1),"—") -> — | Q29: =IF(AND(ISNUMBER(O29),ISNUMBER(P29)),ROUND(O29*(1+P29/30),1),"—") -> — | R29: =IFERROR(MAX(IFERROR(VALUE(E29),0),IFERROR(VALUE(H29),0),IFERROR(VALUE(K29),0),IFERROR(VALUE(N29),0),IFERROR(VALUE(Q29),0)),"—") -> 0
A30: Band pull apart with external rotation | B30: 2x12 reps | E30: =IF(AND(ISNUMBER(C30),ISNUMBER(D30)),ROUND(C30*(1+D30/30),1),"—") -> — | H30: =IF(AND(ISNUMBER(F30),ISNUMBER(G30)),ROUND(F30*(1+G30/30),1),"—") -> — | K30: =IF(AND(ISNUMBER(I30),ISNUMBER(J30)),ROUND(I30*(1+J30/30),1),"—") -> — | N30: =IF(AND(ISNUMBER(L30),ISNUMBER(M30)),ROUND(L30*(1+M30/30),1),"—") -> — | Q30: =IF(AND(ISNUMBER(O30),ISNUMBER(P30)),ROUND(O30*(1+P30/30),1),"—") -> — | R30: =IFERROR(MAX(IFERROR(VALUE(E30),0),IFERROR(VALUE(H30),0),IFERROR(VALUE(K30),0),IFERROR(VALUE(N30),0),IFERROR(VALUE(Q30),0)),"—") -> 0
A31: Pull-ups / assisted pull-ups (wide Grip) | B31: V-taper KING. Band assist if needed. | C31: 78 | D31: 2 | E31: =IF(AND(ISNUMBER(C31),ISNUMBER(D31)),ROUND(C31*(1+D31/30),1),"—") -> 83.2 | F31: 78 | G31: 2 | H31: =IF(AND(ISNUMBER(F31),ISNUMBER(G31)),ROUND(F31*(1+G31/30),1),"—") -> 83.2 | I31: 78 | J31: 2 | K31: =IF(AND(ISNUMBER(I31),ISNUMBER(J31)),ROUND(I31*(1+J31/30),1),"—") -> 83.2 | N31: =IF(AND(ISNUMBER(L31),ISNUMBER(M31)),ROUND(L31*(1+M31/30),1),"—") -> — | Q31: =IF(AND(ISNUMBER(O31),ISNUMBER(P31)),ROUND(O31*(1+P31/30),1),"—") -> — | R31: =IFERROR(MAX(IFERROR(VALUE(E31),0),IFERROR(VALUE(H31),0),IFERROR(VALUE(K31),0),IFERROR(VALUE(N31),0),IFERROR(VALUE(Q31),0)),"—") -> 83.2 | S31: 3 | T31: Max
A32: Dumbbell Bent-Over Row | B32: Elbows back, not flared. Squeeze at top.Mid-back thickness. | C32: 5 | D32: 30 | E32: =IF(AND(ISNUMBER(C32),ISNUMBER(D32)),ROUND(C32*(1+D32/30),1),"—") -> 10 | F32: 7.5 | G32: 20 | H32: =IF(AND(ISNUMBER(F32),ISNUMBER(G32)),ROUND(F32*(1+G32/30),1),"—") -> 12.5 | I32: 10 | J32: 10 | K32: =IF(AND(ISNUMBER(I32),ISNUMBER(J32)),ROUND(I32*(1+J32/30),1),"—") -> 13.3 | L32: 10 | M32: 14 | N32: =IF(AND(ISNUMBER(L32),ISNUMBER(M32)),ROUND(L32*(1+M32/30),1),"—") -> 14.7 | Q32: =IF(AND(ISNUMBER(O32),ISNUMBER(P32)),ROUND(O32*(1+P32/30),1),"—") -> — | R32: =IFERROR(MAX(IFERROR(VALUE(E32),0),IFERROR(VALUE(H32),0),IFERROR(VALUE(K32),0),IFERROR(VALUE(N32),0),IFERROR(VALUE(Q32),0)),"—") -> 14.7 | S32: 3 | T32: 12
A33: Cable/Pulley Lat Pulldown | B33: Wide grip. Pull to upper chest. Stretch at top. | C33: 15 | D33: 20 | E33: =IF(AND(ISNUMBER(C33),ISNUMBER(D33)),ROUND(C33*(1+D33/30),1),"—") -> 25 | F33: 25 | G33: 11 | H33: =IF(AND(ISNUMBER(F33),ISNUMBER(G33)),ROUND(F33*(1+G33/30),1),"—") -> 34.2 | I33: 27.5 | J33: 13 | K33: =IF(AND(ISNUMBER(I33),ISNUMBER(J33)),ROUND(I33*(1+J33/30),1),"—") -> 39.4 | L33: 27.5 | M33: 10 | N33: =IF(AND(ISNUMBER(L33),ISNUMBER(M33)),ROUND(L33*(1+M33/30),1),"—") -> 36.7 | Q33: =IF(AND(ISNUMBER(O33),ISNUMBER(P33)),ROUND(O33*(1+P33/30),1),"—") -> — | R33: =IFERROR(MAX(IFERROR(VALUE(E33),0),IFERROR(VALUE(H33),0),IFERROR(VALUE(K33),0),IFERROR(VALUE(N33),0),IFERROR(VALUE(Q33),0)),"—") -> 39.4 | S33: 3 | T33: 12
A34: Dumbbell Reverse Fly | B34: Rear delts. Slow arc. 3D shoulder look. | C34: 7.5 | D34: 12 | E34: =IF(AND(ISNUMBER(C34),ISNUMBER(D34)),ROUND(C34*(1+D34/30),1),"—") -> 10.5 | F34: 10 | G34: 8 | H34: =IF(AND(ISNUMBER(F34),ISNUMBER(G34)),ROUND(F34*(1+G34/30),1),"—") -> 12.7 | I34: 10 | J34: 6 | K34: =IF(AND(ISNUMBER(I34),ISNUMBER(J34)),ROUND(I34*(1+J34/30),1),"—") -> 12 | N34: =IF(AND(ISNUMBER(L34),ISNUMBER(M34)),ROUND(L34*(1+M34/30),1),"—") -> — | Q34: =IF(AND(ISNUMBER(O34),ISNUMBER(P34)),ROUND(O34*(1+P34/30),1),"—") -> — | R34: =IFERROR(MAX(IFERROR(VALUE(E34),0),IFERROR(VALUE(H34),0),IFERROR(VALUE(K34),0),IFERROR(VALUE(N34),0),IFERROR(VALUE(Q34),0)),"—") -> 12.7 | S34: 3 | T34: 15
A35: Dumbbell Face Pull (bent over) | B35: Elbows high. Rotator cuff + posture. | C35: 7.5 | D35: 10 | E35: =IF(AND(ISNUMBER(C35),ISNUMBER(D35)),ROUND(C35*(1+D35/30),1),"—") -> 10 | F35: 10 | G35: 8 | H35: =IF(AND(ISNUMBER(F35),ISNUMBER(G35)),ROUND(F35*(1+G35/30),1),"—") -> 12.7 | I35: 10 | J35: 8 | K35: =IF(AND(ISNUMBER(I35),ISNUMBER(J35)),ROUND(I35*(1+J35/30),1),"—") -> 12.7 | N35: =IF(AND(ISNUMBER(L35),ISNUMBER(M35)),ROUND(L35*(1+M35/30),1),"—") -> — | Q35: =IF(AND(ISNUMBER(O35),ISNUMBER(P35)),ROUND(O35*(1+P35/30),1),"—") -> — | R35: =IFERROR(MAX(IFERROR(VALUE(E35),0),IFERROR(VALUE(H35),0),IFERROR(VALUE(K35),0),IFERROR(VALUE(N35),0),IFERROR(VALUE(Q35),0)),"—") -> 12.7 | S35: 3 | T35: 15
A36: Dumbbell Hammer Curl | B36: 60° bench. Long head bicep peak. | C36: 7.5 | D36: 11 | E36: =IF(AND(ISNUMBER(C36),ISNUMBER(D36)),ROUND(C36*(1+D36/30),1),"—") -> 10.3 | F36: 7.5 | G36: 11 | H36: =IF(AND(ISNUMBER(F36),ISNUMBER(G36)),ROUND(F36*(1+G36/30),1),"—") -> 10.3 | I36: 7.5 | J36: 6 | K36: =IF(AND(ISNUMBER(I36),ISNUMBER(J36)),ROUND(I36*(1+J36/30),1),"—") -> 9 | N36: =IF(AND(ISNUMBER(L36),ISNUMBER(M36)),ROUND(L36*(1+M36/30),1),"—") -> — | Q36: =IF(AND(ISNUMBER(O36),ISNUMBER(P36)),ROUND(O36*(1+P36/30),1),"—") -> — | R36: =IFERROR(MAX(IFERROR(VALUE(E36),0),IFERROR(VALUE(H36),0),IFERROR(VALUE(K36),0),IFERROR(VALUE(N36),0),IFERROR(VALUE(Q36),0)),"—") -> 10.3 | S36: 3 | T36: 12
A37: Barbell-style curl (DB) | B37: Supinated grip. Full ROM, no swinging. | C37: 7.5 | D37: 10 | E37: =IF(AND(ISNUMBER(C37),ISNUMBER(D37)),ROUND(C37*(1+D37/30),1),"—") -> 10 | F37: 10 | G37: 4 | H37: =IF(AND(ISNUMBER(F37),ISNUMBER(G37)),ROUND(F37*(1+G37/30),1),"—") -> 11.3 | I37: 10 | J37: 3 | K37: =IF(AND(ISNUMBER(I37),ISNUMBER(J37)),ROUND(I37*(1+J37/30),1),"—") -> 11 | N37: =IF(AND(ISNUMBER(L37),ISNUMBER(M37)),ROUND(L37*(1+M37/30),1),"—") -> — | Q37: =IF(AND(ISNUMBER(O37),ISNUMBER(P37)),ROUND(O37*(1+P37/30),1),"—") -> — | R37: =IFERROR(MAX(IFERROR(VALUE(E37),0),IFERROR(VALUE(H37),0),IFERROR(VALUE(K37),0),IFERROR(VALUE(N37),0),IFERROR(VALUE(Q37),0)),"—") -> 11.3
A38: BAG: Hooks + Uppercuts | B38: 3×1 min. Rotate hips. Power from body not arm. | E38: =IF(AND(ISNUMBER(C38),ISNUMBER(D38)),ROUND(C38*(1+D38/30),1),"—") -> — | H38: =IF(AND(ISNUMBER(F38),ISNUMBER(G38)),ROUND(F38*(1+G38/30),1),"—") -> — | K38: =IF(AND(ISNUMBER(I38),ISNUMBER(J38)),ROUND(I38*(1+J38/30),1),"—") -> — | N38: =IF(AND(ISNUMBER(L38),ISNUMBER(M38)),ROUND(L38*(1+M38/30),1),"—") -> — | Q38: =IF(AND(ISNUMBER(O38),ISNUMBER(P38)),ROUND(O38*(1+P38/30),1),"—") -> — | R38: =IFERROR(MAX(IFERROR(VALUE(E38),0),IFERROR(VALUE(H38),0),IFERROR(VALUE(K38),0),IFERROR(VALUE(N38),0),IFERROR(VALUE(Q38),0)),"—") -> 0
A39: Dead hang passive stretch | B39: close grip stretch back while hang, 2x30 sec | E39: =IF(AND(ISNUMBER(C39),ISNUMBER(D39)),ROUND(C39*(1+D39/30),1),"—") -> — | H39: =IF(AND(ISNUMBER(F39),ISNUMBER(G39)),ROUND(F39*(1+G39/30),1),"—") -> — | K39: =IF(AND(ISNUMBER(I39),ISNUMBER(J39)),ROUND(I39*(1+J39/30),1),"—") -> — | N39: =IF(AND(ISNUMBER(L39),ISNUMBER(M39)),ROUND(L39*(1+M39/30),1),"—") -> — | Q39: =IF(AND(ISNUMBER(O39),ISNUMBER(P39)),ROUND(O39*(1+P39/30),1),"—") -> — | R39: =IFERROR(MAX(IFERROR(VALUE(E39),0),IFERROR(VALUE(H39),0),IFERROR(VALUE(K39),0),IFERROR(VALUE(N39),0),IFERROR(VALUE(Q39),0)),"—") -> 0
A40: Doorway lat stretch | B40: 30 sec each side | E40: =IF(AND(ISNUMBER(C40),ISNUMBER(D40)),ROUND(C40*(1+D40/30),1),"—") -> — | H40: =IF(AND(ISNUMBER(F40),ISNUMBER(G40)),ROUND(F40*(1+G40/30),1),"—") -> — | K40: =IF(AND(ISNUMBER(I40),ISNUMBER(J40)),ROUND(I40*(1+J40/30),1),"—") -> — | N40: =IF(AND(ISNUMBER(L40),ISNUMBER(M40)),ROUND(L40*(1+M40/30),1),"—") -> — | Q40: =IF(AND(ISNUMBER(O40),ISNUMBER(P40)),ROUND(O40*(1+P40/30),1),"—") -> — | R40: =IFERROR(MAX(IFERROR(VALUE(E40),0),IFERROR(VALUE(H40),0),IFERROR(VALUE(K40),0),IFERROR(VALUE(N40),0),IFERROR(VALUE(Q40),0)),"—") -> 0
...

Sheet Strength Progress
A1: 📈 Strength Progress — 1RM Tracker
A2: Best estimated 1RM per exercise per session. Add a new column each time you train.
A4: Exercise | B4: Session 1 | C4: Session 2 | D4: Session 3 | E4: Session 4 | F4: Session 5 | G4: Session 6 | H4: Session 7 | I4: Session 8 | J4: Session 9 | K4: Session 10 | L4: Session 11 | M4: Session 12 | N4: Session 13 | O4: Session 14 | P4: Session 15 | Q4: Session 16 | R4: Session 17 | S4: Session 18 | T4: Session 19 | U4: Session 20 | V4: Session 21 | W4: Session 22 | X4: Session 23 | Y4: Session 24
A5: Dumbbell flat bench press | B5: ='Exercise Plan'!R9 -> 12.5 | C5: =IFERROR((OFFSET('Exercise Plan'!R9,(COLUMN()-2)*40,0)-OFFSET('Exercise Plan'!R9,(COLUMN()-3)*40,0))/OFFSET('Exercise Plan'!R9,(COLUMN()-3)*40,0)+1,"N/A") -> N/A | D5: =IFERROR((OFFSET('Exercise Plan'!R9,(COLUMN()-2)*40,0)-OFFSET('Exercise Plan'!R9,(COLUMN()-3)*40,0))/OFFSET('Exercise Plan'!R9,(COLUMN()-3)*40,0)+1,"N/A") -> N/A
A6: Dumbbell incline press | B6: ='Exercise Plan'!R10 -> 12.5 | C6: =IFERROR((OFFSET('Exercise Plan'!R10,(COLUMN()-2)*40,0)-OFFSET('Exercise Plan'!R10,(COLUMN()-3)*40,0))/OFFSET('Exercise Plan'!R10,(COLUMN()-3)*40,0)+1,"N/A") -> 0 | D6: =IFERROR((OFFSET('Exercise Plan'!R10,(COLUMN()-2)*40,0)-OFFSET('Exercise Plan'!R10,(COLUMN()-3)*40,0))/OFFSET('Exercise Plan'!R10,(COLUMN()-3)*40,0)+1,"N/A") -> N/A
A7: Dumbbell lateral raise | B7: ='Exercise Plan'!R11 -> 10 | C7: =IFERROR((OFFSET('Exercise Plan'!R11,(COLUMN()-2)*40,0)-OFFSET('Exercise Plan'!R11,(COLUMN()-3)*40,0))/OFFSET('Exercise Plan'!R11,(COLUMN()-3)*40,0)+1,"N/A") -> 0 | D7: =IFERROR((OFFSET('Exercise Plan'!R11,(COLUMN()-2)*40,0)-OFFSET('Exercise Plan'!R11,(COLUMN()-3)*40,0))/OFFSET('Exercise Plan'!R11,(COLUMN()-3)*40,0)+1,"N/A") -> N/A
A8: Standing dumbbell OHP | B8: ='Exercise Plan'!R12 -> 18.5 | C8: =IFERROR((OFFSET('Exercise Plan'!R12,(COLUMN()-2)*40,0)-OFFSET('Exercise Plan'!R12,(COLUMN()-3)*40,0))/OFFSET('Exercise Plan'!R12,(COLUMN()-3)*40,0)+1,"N/A") -> 0 | D8: =IFERROR((OFFSET('Exercise Plan'!R12,(COLUMN()-2)*40,0)-OFFSET('Exercise Plan'!R12,(COLUMN()-3)*40,0))/OFFSET('Exercise Plan'!R12,(COLUMN()-3)*40,0)+1,"N/A") -> N/A
A9: Cable/Band Chest Fly | B9: ='Exercise Plan'!R13 -> 23.5 | C9: =IFERROR((OFFSET('Exercise Plan'!R13,(COLUMN()-2)*40,0)-OFFSET('Exercise Plan'!R13,(COLUMN()-3)*40,0))/OFFSET('Exercise Plan'!R13,(COLUMN()-3)*40,0)+1,"N/A") -> 0 | D9: =IFERROR((OFFSET('Exercise Plan'!R13,(COLUMN()-2)*40,0)-OFFSET('Exercise Plan'!R13,(COLUMN()-3)*40,0))/OFFSET('Exercise Plan'!R13,(COLUMN()-3)*40,0)+1,"N/A") -> N/A
A10: Tricep Cable/Band Pushdown | B10: ='Exercise Plan'!R14 -> 21 | C10: =IFERROR((OFFSET('Exercise Plan'!R14,(COLUMN()-2)*40,0)-OFFSET('Exercise Plan'!R14,(COLUMN()-3)*40,0))/OFFSET('Exercise Plan'!R14,(COLUMN()-3)*40,0)+1,"N/A") -> 0 | D10: =IFERROR((OFFSET('Exercise Plan'!R14,(COLUMN()-2)*40,0)-OFFSET('Exercise Plan'!R14,(COLUMN()-3)*40,0))/OFFSET('Exercise Plan'!R14,(COLUMN()-3)*40,0)+1,"N/A") -> N/A
A11: Overhead DB Tricep Extension | B11: ='Exercise Plan'!R15 -> 11 | C11: =IFERROR((OFFSET('Exercise Plan'!R15,(COLUMN()-2)*40,0)-OFFSET('Exercise Plan'!R15,(COLUMN()-3)*40,0))/OFFSET('Exercise Plan'!R15,(COLUMN()-3)*40,0)+1,"N/A") -> 0 | D11: =IFERROR((OFFSET('Exercise Plan'!R15,(COLUMN()-2)*40,0)-OFFSET('Exercise Plan'!R15,(COLUMN()-3)*40,0))/OFFSET('Exercise Plan'!R15,(COLUMN()-3)*40,0)+1,"N/A") -> N/A
A12: Dumbbell Arnold Press | B12: ='Exercise Plan'!R75 -> 13 | C12: =IFERROR((OFFSET('Exercise Plan'!R75,(COLUMN()-2)*40,0)-OFFSET('Exercise Plan'!R75,(COLUMN()-3)*40,0))/OFFSET('Exercise Plan'!R75,(COLUMN()-3)*40,0)+1,"N/A") -> 0 | D12: =IFERROR((OFFSET('Exercise Plan'!R16,(COLUMN()-2)*40,0)-OFFSET('Exercise Plan'!R16,(COLUMN()-3)*40,0))/OFFSET('Exercise Plan'!R16,(COLUMN()-3)*40,0)+1,"N/A") -> N/A
A13: Dumbbell front raise | B13: ='Exercise Plan'!R76 -> 12.7 | C13: =IFERROR((OFFSET('Exercise Plan'!R76,(COLUMN()-2)*40,0)-OFFSET('Exercise Plan'!R76,(COLUMN()-3)*40,0))/OFFSET('Exercise Plan'!R76,(COLUMN()-3)*40,0)+1,"N/A") -> 0 | D13: =IFERROR((OFFSET('Exercise Plan'!R17,(COLUMN()-2)*40,0)-OFFSET('Exercise Plan'!R17,(COLUMN()-3)*40,0))/OFFSET('Exercise Plan'!R17,(COLUMN()-3)*40,0)+1,"N/A") -> N/A
A14: Dumbbell Lateral Raise (drop set) | B14: ='Exercise Plan'!R77 -> 9.3 | C14: =IFERROR((OFFSET('Exercise Plan'!R77,(COLUMN()-2)*40,0)-OFFSET('Exercise Plan'!R77,(COLUMN()-3)*40,0))/OFFSET('Exercise Plan'!R77,(COLUMN()-3)*40,0)+1,"N/A") -> 0 | D14: =IFERROR((OFFSET('Exercise Plan'!R18,(COLUMN()-2)*40,0)-OFFSET('Exercise Plan'!R18,(COLUMN()-3)*40,0))/OFFSET('Exercise Plan'!R18,(COLUMN()-3)*40,0)+1,"N/A") -> N/A
A15: Push-ups (feet elevated) | B15: ='Exercise Plan'!R78 -> 0 | C15: =IFERROR((OFFSET('Exercise Plan'!R78,(COLUMN()-2)*40,0)-OFFSET('Exercise Plan'!R78,(COLUMN()-3)*40,0))/OFFSET('Exercise Plan'!R78,(COLUMN()-3)*40,0)+1,"N/A") -> N/A | D15: =IFERROR((OFFSET('Exercise Plan'!R19,(COLUMN()-2)*40,0)-OFFSET('Exercise Plan'!R19,(COLUMN()-3)*40,0))/OFFSET('Exercise Plan'!R19,(COLUMN()-3)*40,0)+1,"N/A") -> N/A
A16: Dumbbell decline press | B16: ='Exercise Plan'!R79 -> 16.7 | C16: =IFERROR((OFFSET('Exercise Plan'!R79,(COLUMN()-2)*40,0)-OFFSET('Exercise Plan'!R79,(COLUMN()-3)*40,0))/OFFSET('Exercise Plan'!R79,(COLUMN()-3)*40,0)+1,"N/A") -> 0 | D16: =IFERROR((OFFSET('Exercise Plan'!R20,(COLUMN()-2)*40,0)-OFFSET('Exercise Plan'!R20,(COLUMN()-3)*40,0))/OFFSET('Exercise Plan'!R20,(COLUMN()-3)*40,0)+1,"N/A") -> N/A
A17: Cable/Band overhead tricep | B17: ='Exercise Plan'!R80 -> 20 | C17: =IFERROR((OFFSET('Exercise Plan'!R80,(COLUMN()-2)*40,0)-OFFSET('Exercise Plan'!R80,(COLUMN()-3)*40,0))/OFFSET('Exercise Plan'!R80,(COLUMN()-3)*40,0)+1,"N/A") -> 0 | D17: =IFERROR((OFFSET('Exercise Plan'!R21,(COLUMN()-2)*40,0)-OFFSET('Exercise Plan'!R21,(COLUMN()-3)*40,0))/OFFSET('Exercise Plan'!R21,(COLUMN()-3)*40,0)+1,"N/A") -> N/A
A18: Diamond push-ups | B18: ='Exercise Plan'!R81 -> 0 | C18: =IFERROR((OFFSET('Exercise Plan'!R81,(COLUMN()-2)*40,0)-OFFSET('Exercise Plan'!R81,(COLUMN()-3)*40,0))/OFFSET('Exercise Plan'!R81,(COLUMN()-3)*40,0)+1,"N/A") -> N/A
A19: Pull-ups / assisted pull-ups (wide Grip) | B19: =#REF! -> #REF! | C19: =IFERROR(((OFFSET(#REF!,40,0)-#REF!)/#REF!)+1,"N/A") -> N/A
A20: Dumbbell Bent-Over Row | B20: =#REF! -> #REF! | C20: =IFERROR(((OFFSET(#REF!,40,0)-#REF!)/#REF!)+1,"N/A") -> N/A
A21: Cable/Pulley Lat Pulldown | B21: =#REF! -> #REF! | C21: =IFERROR(((OFFSET(#REF!,40,0)-#REF!)/#REF!)+1,"N/A") -> N/A
A22: Dumbbell Reverse Fly | B22: =#REF! -> #REF! | C22: =IFERROR(((OFFSET(#REF!,40,0)-#REF!)/#REF!)+1,"N/A") -> N/A
A23: Dumbbell Face Pull (bent over) | B23: =#REF! -> #REF! | C23: =IFERROR(((OFFSET(#REF!,40,0)-#REF!)/#REF!)+1,"N/A") -> N/A
A24: Dumbbell Hammer Curl | B24: =#REF! -> #REF! | C24: =IFERROR(((OFFSET(#REF!,40,0)-#REF!)/#REF!)+1,"N/A") -> N/A
A25: Barbell-style curl (DB) | B25: =#REF! -> #REF! | C25: =IFERROR(((OFFSET(#REF!,40,0)-#REF!)/#REF!)+1,"N/A") -> N/A
A26: Wide-grip pull-ups | B26: =#REF! -> #REF! | C26: =IFERROR(((OFFSET(#REF!,40,0)-#REF!)/#REF!)+1,"N/A") -> N/A
A27: Cable/pulley seated row | B27: =#REF! -> #REF! | C27: =IFERROR(((OFFSET(#REF!,40,0)-#REF!)/#REF!)+1,"N/A") -> N/A
A28: Single-arm dumbbell row | B28: =#REF! -> #REF! | C28: =IFERROR(((OFFSET(#REF!,40,0)-#REF!)/#REF!)+1,"N/A") -> N/A
A29: Dumbbell shrug | B29: =#REF! -> #REF! | C29: =IFERROR(((OFFSET(#REF!,40,0)-#REF!)/#REF!)+1,"N/A") -> N/A
A30: Resistance band pull-apart (supinated) | B30: =#REF! -> #REF! | C30: =IFERROR(((OFFSET(#REF!,40,0)-#REF!)/#REF!)+1,"N/A") -> N/A
A31: Incline dumbbell curl | B31: =#REF! -> #REF! | C31: =IFERROR(((OFFSET(#REF!,40,0)-#REF!)/#REF!)+1,"N/A") -> N/A
A32: Concentration curl | B32: =#REF! -> #REF! | C32: =IFERROR(((OFFSET('Exercise Plan'!R81,40,0)-'Exercise Plan'!R81)/'Exercise Plan'!R81)+1,"N/A") -> N/A
A33: Dumbbell Goblet Squat | B33: =#REF! -> #REF! | C33: =IFERROR(((OFFSET(#REF!,40,0)-#REF!)/#REF!)+1,"N/A") -> N/A
A34: Dumbbell Romanian Deadlift | B34: =#REF! -> #REF! | C34: =IFERROR(((OFFSET(#REF!,40,0)-#REF!)/#REF!)+1,"N/A") -> N/A
A35: Dumbbell Reverse Lunge | B35: =#REF! -> #REF! | C35: =IFERROR(((OFFSET(#REF!,40,0)-#REF!)/#REF!)+1,"N/A") -> N/A
A36: Resistance Band Squat | B36: =#REF! -> #REF! | C36: =IFERROR(((OFFSET(#REF!,40,0)-#REF!)/#REF!)+1,"N/A") -> N/A
A37: Dumbbell Sumo Squat | B37: =#REF! -> #REF! | C37: =IFERROR(((OFFSET(#REF!,40,0)-#REF!)/#REF!)+1,"N/A") -> N/A
A38: Ab Wheel Rollout | B38: =#REF! -> #REF! | C38: =IFERROR(((OFFSET(#REF!,40,0)-#REF!)/#REF!)+1,"N/A") -> N/A
A39: Hanging Knee Raises (Pull-up Bar) | B39: =#REF! -> #REF! | C39: =IFERROR(((OFFSET(#REF!,40,0)-#REF!)/#REF!)+1,"N/A") -> N/A
A40: Plank Variations | B40: =#REF! -> #REF! | C40: =IFERROR(((OFFSET(#REF!,40,0)-#REF!)/#REF!)+1,"N/A") -> N/A
A41: Dumbbell Stiff-Leg Deadlift | B41: =#REF! -> #REF! | C41: =IFERROR(((OFFSET(#REF!,40,0)-#REF!)/#REF!)+1,"N/A") -> N/A
...
